Workbook

Sheet 📋 Daily Log
A1: 📋 TRS DAILY OPERATIONS LOG — 2026
A2: Tubular Running Services · Eastern Province, KSA · ⬇ Enter new jobs below — dashboards auto-update
A4: # | B4: Date | C4: Customer | D4: Rig ID | E4: Well No. | F4: Service Type | G4: Tool Type | H4: Size (in) | I4: Revenue (USD) | J4: Job Hrs | K4: Joints | L4: Jts / Hr | M4: NPT Hrs | N4: NPT Category | O4: Status | P4: Notes
A5: 1 | B5: 46113 | C5: A | D5: RIG-04 | E5: W-132 | F5: Casing | G5: PULD Tool | H5: 5.5 | I5: 5679 | J5: 18.7 | K5: 170 | L5: 11.26 | M5: 3.6 | N5: Equipment | O5: FINISHED
A6: 2 | B6: 46113 | C6: A | D6: RIG-04 | E6: W-325 | F6: Casing | G6: CDS System | H6: 5.5 | I6: 9064 | J6: 4.5 | K6: 46 | L6: 10.22 | M6: 0 | O6: FINISHED
A7: 3 | B7: 46113 | C7: C | D7: RIG-02 | E7: W-320 | F7: Combo | G7: PULD Tool | H7: 4.5 | I7: 12106 | J7: 7.2 | K7: 90 | L7: 12.5 | M7: 0 | O7: FINISHED
A8: 4 | B8: 46114 | C8: A | D8: RIG-06 | E8: W-570 | F8: Casing | G8: Manual Tong | H8: 4.5 | I8: 7308 | J8: 10.9 | K8: 135 | L8: 12.39 | M8: 0 | O8: FINISHED
A9: 5 | B9: 46114 | C9: D | D9: RIG-06 | E9: W-171 | F9: Casing | G9: Manual Tong | H9: 4.5 | I9: 9624 | J9: 20.6 | K9: 232 | L9: 13.49 | M9: 3.4 | N9: Process | O9: FINISHED
A10: 6 | B10: 46115 | C10: B | D10: RIG-02 | E10: W-479 | F10: CDS | G10: Power Tong | H10: 5.5 | I10: 13398 | J10: 11.6 | K10: 131 | L10: 11.29 | M10: 0 | O10: FINISHED
A11: 7 | B11: 46116 | C11: B | D11: RIG-04 | E11: W-376 | F11: CDS | G11: Power Tong | H11: 13.375 | I11: 10620 | J11: 14.7 | K11: 70 | L11: 4.76 | M11: 0 | O11: OPEN
A12: 8 | B12: 46116 | C12: D | D12: RIG-01 | E12: W-316 | F12: Tubing | G12: PULD Tool | H12: 4.5 | I12: 5749 | J12: 4.6 | K12: 56 | L12: 12.17 | M12: 0 | O12: FINISHED
A13: 9 | B13: 46117 | C13: E | D13: RIG-02 | E13: W-862 | F13: Tubing | G13: Manual Tong | H13: 9.625 | I13: 13616 | J13: 16.9 | K13: 108 | L13: 6.39 | M13: 0 | O13: FINISHED
A14: 10 | B14: 46117 | C14: D | D14: RIG-05 | E14: W-605 | F14: Combo | G14: PULD Tool | H14: 13.375 | I14: 8141 | J14: 15.7 | K14: 65 | L14: 4.14 | M14: 0 | O14: FINISHED
A15: 11 | B15: 46117 | C15: A | D15: RIG-04 | E15: W-490 | F15: Casing | G15: Power Tong | H15: 5.5 | I15: 10529 | J15: 19.8 | K15: 208 | L15: 10.51 | M15: 0 | O15: FINISHED
A16: 12 | B16: 46118 | C16: C | D16: RIG-06 | E16: W-448 | F16: Combo | G16: PULD Tool | H16: 13.375 | I16: 13329 | J16: 4.2 | K16: 7 | L16: 4.67 | M16: 2.7 | N16: Process | O16: FINISHED
A17: 13 | B17: 46118 | C17: A | D17: RIG-05 | E17: W-208 | F17: CDS | G17: Manual Tong | H17: 5.5 | I17: 8445 | J17: 23.1 | K17: 224 | L17: 10.18 | M17: 1.1 | N17: Process | O17: FINISHED
A18: 14 | B18: 46118 | C18: E | D18: RIG-05 | E18: W-431 | F18: Combo | G18: Running Tool | H18: 5.5 | I18: 4834 | J18: 19.3 | K18: 170 | L18: 10.49 | M18: 3.1 | N18: Process | O18: FINISHED
A19: 15 | B19: 46119 | C19: A | D19: RIG-05 | E19: W-884 | F19: Casing | G19: PULD Tool | H19: 7 | I19: 5873 | J19: 8.8 | K19: 78 | L19: 9.18 | M19: 0.3 | N19: Client/3rd | O19: FINISHED
A20: 16 | B20: 46119 | C20: B | D20: RIG-06 | E20: W-419 | F20: Tubing | G20: Manual Tong | H20: 13.375 | I20: 4982 | J20: 14.6 | K20: 48 | L20: 4.49 | M20: 3.9 | N20: Process | O20: FINISHED
A21: 17 | B21: 46120 | C21: E | D21: RIG-05 | E21: W-335 | F21: PULD | G21: Running Tool | H21: 9.625 | I21: 4452 | J21: 8.5 | K21: 53 | L21: 6.24 | M21: 0 | O21: FINISHED
A22: 18 | B22: 46120 | C22: D | D22: RIG-03 | E22: W-172 | F22: Tubing | G22: Power Tong | H22: 4.5 | I22: 11494 | J22: 5.2 | K22: 69 | L22: 13.27 | M22: 0 | O22: FINISHED
A23: 19 | B23: 46121 | C23: B | D23: RIG-04 | E23: W-294 | F23: CDS | G23: Manual Tong | H23: 5.5 | I23: 9471 | J23: 18.5 | K23: 187 | L23: 11.54 | M23: 2.3 | N23: Personnel | O23: OPEN
A24: 20 | B24: 46121 | C24: A | D24: RIG-04 | E24: W-845 | F24: Casing | G24: Manual Tong | H24: 7 | I24: 8083 | J24: 13.3 | K24: 88 | L24: 8.3 | M24: 2.7 | N24: Equipment | O24: FINISHED
A25: 21 | B25: 46121 | C25: E | D25: RIG-04 | E25: W-355 | F25: Casing | G25: CDS System | H25: 5.5 | I25: 5283 | J25: 13 | K25: 150 | L25: 11.54 | M25: 0 | O25: FINISHED
A26: 22 | B26: 46122 | C26: C | D26: RIG-02 | E26: W-270 | F26: Combo | G26: Power Tong | H26: 4.5 | I26: 10826 | J26: 14.8 | K26: 198 | L26: 13.38 | M26: 0 | O26: FINISHED
A27: 23 | B27: 46123 | C27: C | D27: RIG-03 | E27: W-902 | F27: PULD | G27: CDS System | H27: 9.625 | I27: 13829 | J27: 7.3 | K27: 46 | L27: 6.3 | M27: 0 | O27: OPEN
A28: 24 | B28: 46123 | C28: C | D28: RIG-01 | E28: W-693 | F28: CDS | G28: Manual Tong | H28: 13.375 | I28: 10942 | J28: 13.7 | K28: 58 | L28: 4.23 | M28: 0 | O28: FINISHED
A29: 25 | B29: 46124 | C29: D | D29: RIG-01 | E29: W-971 | F29: Casing | G29: PULD Tool | H29: 4.5 | I29: 3602 | J29: 13.5 | K29: 159 | L29: 13.95 | M29: 2.1 | N29: Equipment | O29: FINISHED
A30: 26 | B30: 46124 | C30: B | D30: RIG-02 | E30: W-692 | F30: Casing | G30: Running Tool | H30: 4.5 | I30: 11103 | J30: 8.7 | K30: 110 | L30: 12.64 | M30: 0 | O30: FINISHED
A31: 27 | B31: 46124 | C31: D | D31: RIG-02 | E31: W-371 | F31: Casing | G31: Running Tool | H31: 4.5 | I31: 8031 | J31: 15.7 | K31: 146 | L31: 12.17 | M31: 3.7 | N31: Personnel | O31: FINISHED
A32: 28 | B32: 46125 | C32: B | D32: RIG-05 | E32: W-202 | F32: CDS | G32: Manual Tong | H32: 7 | I32: 14148 | J32: 22.7 | K32: 191 | L32: 8.41 | M32: 0 | O32: FINISHED
A33: 29 | B33: 46125 | C33: A | D33: RIG-02 | E33: W-548 | F33: Combo | G33: CDS System | H33: 13.375 | I33: 6182 | J33: 22.7 | K33: 91 | L33: 4.74 | M33: 3.5 | N33: Weather | O33: FINISHED
A34: 30 | B34: 46126 | C34: E | D34: RIG-01 | E34: W-209 | F34: Combo | G34: Running Tool | H34: 4.5 | I34: 11014 | J34: 15.1 | K34: 194 | L34: 13.2 | M34: 0.4 | N34: Personnel | O34: FINISHED
A35: 31 | B35: 46126 | C35: D | D35: RIG-05 | E35: W-600 | F35: Tubing | G35: PULD Tool | H35: 7 | I35: 10258 | J35: 18.4 | K35: 174 | L35: 9.46 | M35: 0 | O35: FINISHED
A36: 32 | B36: 46126 | C36: E | D36: RIG-06 | E36: W-368 | F36: Casing | G36: Power Tong | H36: 9.625 | I36: 12952 | J36: 4.9 | K36: 33 | L36: 6.73 | M36: 0 | O36: FINISHED
A37: 33 | B37: 46127 | C37: C | D37: RIG-03 | E37: W-696 | F37: Combo | G37: Manual Tong | H37: 13.375 | I37: 3116 | J37: 5.5 | K37: 9 | L37: 4.74 | M37: 3.6 | N37: Process | O37: FINISHED
A38: 34 | B38: 46128 | C38: B | D38: RIG-06 | E38: W-355 | F38: PULD | G38: CDS System | H38: 4.5 | I38: 6699 | J38: 22 | K38: 260 | L38: 13.98 | M38: 3.4 | N38: Weather | O38: FINISHED
A39: 35 | B39: 46128 | C39: A | D39: RIG-04 | E39: W-125 | F39: CDS | G39: Running Tool | H39: 9.625 | I39: 14686 | J39: 19 | K39: 115 | L39: 6.35 | M39: 0.9 | N39: Personnel | O39: FINISHED
A40: 36 | B40: 46128 | C40: B | D40: RIG-04 | E40: W-327 | F40: CDS | G40: Manual Tong | H40: 5.5 | I40: 6202 | J40: 19.7 | K40: 219 | L40: 11.12 | M40: 0 | O40: FINISHED
A41: 37 | B41: 46129 | C41: C | D41: RIG-01 | E41: W-891 | F41: CDS | G41: PULD Tool | H41: 5.5 | I41: 5675 | J41: 17.2 | K41: 199 | L41: 11.57 | M41: 0 | O41: FINISHED
...

Sheet 📊 KPI Summary
A1: 🔧 TRS OPERATIONS — KPI SUMMARY DASHBOARD
A2: Tubular Running Services · 🔄 Auto-calculated from Daily Log ·
A5: 💰 TOTAL REVENUE | E5: 📋 TOTAL JOBS | I5: ⏱ OVERALL NPT % | M5: 📈 AVG REVENUE / JOB
A6: =SUM('📋 Daily Log'!$I$5:$I$5000) -> 568310 | E6: =SUMPRODUCT(('📋 Daily Log'!$C$5:$C$5000<>"")*1) -> 63 | I6: =IFERROR(SUM('📋 Daily Log'!$M$5:$M$5000)/SUM('📋 Daily Log'!$J$5:$J$5000),0) -> 0.083949748 | M6: =IFERROR(SUM('📋 Daily Log'!$I$5:$I$5000)/SUMPRODUCT(('📋 Daily Log'!$C$5:$C$5000<>"")*1),0) -> 9020.7937
A7: "USD · Month to Date" | E7: =COUNTIF('📋 Daily Log'!$O$5:$O$5000,"FINISHED")&" finished "&COUNTIF('📋 Daily Log'!$O$5:$O$5000,"OPEN")&" open" -> 56 finished 7 open | I7: ="Total NPT: "&TEXT(SUM('📋 Daily Log'!$M$5:$M$5000),"0.0")&" hrs" -> Total NPT: 71.5 hrs | M7: "USD per completed job"
A11: ⚡ REVENUE / HOUR | E11: ✅ COMPLETION RATE | I11: 🔩 JOINTS / HOUR | M11: 📦 TOTAL JOINTS RUN
A12: =IFERROR(SUM('📋 Daily Log'!$I$5:$I$5000)/SUM('📋 Daily Log'!$J$5:$J$5000),0) -> 667.26547 | E12: =IFERROR(COUNTIF('📋 Daily Log'!$O$5:$O$5000,"FINISHED")/SUMPRODUCT(('📋 Daily Log'!$C$5:$C$5000<>"")*1),0) -> 0.88888889 | I12: =IFERROR(SUM('📋 Daily Log'!$K$5:$K$5000)/(SUM('📋 Daily Log'!$J$5:$J$5000)-SUM('📋 Daily Log'!$M$5:$M$5000)),0) -> 8.9079723 | M12: =SUM('📋 Daily Log'!$K$5:$K$5000) -> 6950
A13: "USD per operational hour" | E13: =COUNTIF('📋 Daily Log'!$O$5:$O$5000,"FINISHED")&" of "&SUMPRODUCT(('📋 Daily Log'!$C$5:$C$5000<>"")*1)&" jobs closed" -> 56 of 63 jobs closed | I13: ="Based on "&TEXT(SUM('📋 Daily Log'!$J$5:$J$5000)-SUM('📋 Daily Log'!$M$5:$M$5000),"0.0")&" productive hrs" -> Based on 780.2 productive hrs | M13: "All jobs this period"
A17: 📊 AVG JOINTS / JOB | E17: ⏳ AVG HOURS / JOB | I17: 🏭 JOBS / HOUR | M17: ⚠️ NPT INCIDENT RATE
A18: =IFERROR(SUM('📋 Daily Log'!$K$5:$K$5000)/SUMPRODUCT(('📋 Daily Log'!$C$5:$C$5000<>"")*1),0) -> 110.31746 | E18: =IFERROR(SUM('📋 Daily Log'!$J$5:$J$5000)/SUMPRODUCT(('📋 Daily Log'!$C$5:$C$5000<>"")*1),0) -> 13.519048 | I18: =IFERROR(SUMPRODUCT(('📋 Daily Log'!$C$5:$C$5000<>"")*1)/SUM('📋 Daily Log'!$J$5:$J$5000),0) -> 0.073969708 | M18: =IFERROR(SUMPRODUCT(('📋 Daily Log'!$M$5:$M$5000>0)*1)/SUMPRODUCT(('📋 Daily Log'!$C$5:$C$5000<>"")*1),0) -> 0.49206349
A19: =SUMPRODUCT(('📋 Daily Log'!$C$5:$C$5000<>"")*1)&" total jobs recorded" -> 63 total jobs recorded | E19: "Average duration per job" | I19: ="1 job every "&TEXT(IFERROR(SUM('📋 Daily Log'!$J$5:$J$5000)/SUMPRODUCT(('📋 Daily Log'!$C$5:$C$5000<>"")*1),0),"0.0 hrs avg") -> #VALUE! | M19: =SUMPRODUCT(('📋 Daily Log'!$M$5:$M$5000>0)*1)&" of "&SUMPRODUCT(('📋 Daily Log'!$C$5:$C$5000<>"")*1)&" jobs had NPT" -> 31 of 63 jobs had NPT
A22: 👤 PERFORMANCE BY CUSTOMER
A23: Name | B23: Jobs | C23: Revenue | D23: Avg/Job | E23: Joints | F23: Jts/Hr | G23: NPT Hrs | H23: NPT%
A24: B | B24: {=SUMPRODUCT(('📋 Daily Log'!$C$5:$C$5000="C")*1)} -> 13 | C24: {=SUMPRODUCT(('📋 Daily Log'!$C$5:$C$5000="C")*('📋 Daily Log'!$I$5:$I$5000))} -> 132321 | D24: {=IFERROR(SUMPRODUCT(('📋 Daily Log'!$C$5:$C$5000="C")*('📋 Daily Log'!$I$5:$I$5000))/SUMPRODUCT(('📋 Daily Log'!$C$5:$C$5000="C")*1),0)} -> 10178.538 | E24: {=SUMPRODUCT(('📋 Daily Log'!$C$5:$C$5000="C")*('📋 Daily Log'!$K$5:$K$5000))} -> 1105 | F24: {=IFERROR(SUMPRODUCT(('📋 Daily Log'!$C$5:$C$5000="C")*('📋 Daily Log'!$K$5:$K$5000))/(SUMPRODUCT(('📋 Daily Log'!$C$5:$C$5000="C")*('📋 Daily Log'!$J$5:$J$5000))-SUMPRODUCT(('📋 Daily Log'!$C$5:$C$5000="C")*('📋 Daily Log'!$M$5:$M$5000))),0)} -> 7.8480114 | G24: {=SUMPRODUCT(('📋 Daily Log'!$C$5:$C$5000="C")*('📋 Daily Log'!$M$5:$M$5000))} -> 16.2 | H24: {=IFERROR(SUMPRODUCT(('📋 Daily Log'!$C$5:$C$5000="C")*('📋 Daily Log'!$M$5:$M$5000))/SUMPRODUCT(('📋 Daily Log'!$C$5:$C$5000="C")*('📋 Daily Log'!$J$5:$J$5000)),0)} -> 0.10318471
A25: A | B25: {=SUMPRODUCT(('📋 Daily Log'!$C$5:$C$5000="B")*1)} -> 14 | C25: {=SUMPRODUCT(('📋 Daily Log'!$C$5:$C$5000="B")*('📋 Daily Log'!$I$5:$I$5000))} -> 130478 | D25: {=IFERROR(SUMPRODUCT(('📋 Daily Log'!$C$5:$C$5000="B")*('📋 Daily Log'!$I$5:$I$5000))/SUMPRODUCT(('📋 Daily Log'!$C$5:$C$5000="B")*1),0)} -> 9319.8571 | E25: {=SUMPRODUCT(('📋 Daily Log'!$C$5:$C$5000="B")*('📋 Daily Log'!$K$5:$K$5000))} -> 1807 | F25: {=IFERROR(SUMPRODUCT(('📋 Daily Log'!$C$5:$C$5000="B")*('📋 Daily Log'!$K$5:$K$5000))/(SUMPRODUCT(('📋 Daily Log'!$C$5:$C$5000="B")*('📋 Daily Log'!$J$5:$J$5000))-SUMPRODUCT(('📋 Daily Log'!$C$5:$C$5000="B")*('📋 Daily Log'!$M$5:$M$5000))),0)} -> 9.4458965 | G25: {=SUMPRODUCT(('📋 Daily Log'!$C$5:$C$5000="B")*('📋 Daily Log'!$M$5:$M$5000))} -> 14.6 | H25: {=IFERROR(SUMPRODUCT(('📋 Daily Log'!$C$5:$C$5000="B")*('📋 Daily Log'!$M$5:$M$5000))/SUMPRODUCT(('📋 Daily Log'!$C$5:$C$5000="B")*('📋 Daily Log'!$J$5:$J$5000)),0)} -> 0.070908208
A26: C | B26: {=SUMPRODUCT(('📋 Daily Log'!$C$5:$C$5000="E")*1)} -> 13 | C26: {=SUMPRODUCT(('📋 Daily Log'!$C$5:$C$5000="E")*('📋 Daily Log'!$I$5:$I$5000))} -> 121079 | D26: {=IFERROR(SUMPRODUCT(('📋 Daily Log'!$C$5:$C$5000="E")*('📋 Daily Log'!$I$5:$I$5000))/SUMPRODUCT(('📋 Daily Log'!$C$5:$C$5000="E")*1),0)} -> 9313.7692 | E26: {=SUMPRODUCT(('📋 Daily Log'!$C$5:$C$5000="E")*('📋 Daily Log'!$K$5:$K$5000))} -> 1175 | F26: {=IFERROR(SUMPRODUCT(('📋 Daily Log'!$C$5:$C$5000="E")*('📋 Daily Log'!$K$5:$K$5000))/(SUMPRODUCT(('📋 Daily Log'!$C$5:$C$5000="E")*('📋 Daily Log'!$J$5:$J$5000))-SUMPRODUCT(('📋 Daily Log'!$C$5:$C$5000="E")*('📋 Daily Log'!$M$5:$M$5000))),0)} -> 8.0424367 | G26: {=SUMPRODUCT(('📋 Daily Log'!$C$5:$C$5000="E")*('📋 Daily Log'!$M$5:$M$5000))} -> 11 | H26: {=IFERROR(SUMPRODUCT(('📋 Daily Log'!$C$5:$C$5000="E")*('📋 Daily Log'!$M$5:$M$5000))/SUMPRODUCT(('📋 Daily Log'!$C$5:$C$5000="E")*('📋 Daily Log'!$J$5:$J$5000)),0)} -> 0.070019096
A27: D | B27: {=SUMPRODUCT(('📋 Daily Log'!$C$5:$C$5000="D")*1)} -> 12 | C27: {=SUMPRODUCT(('📋 Daily Log'!$C$5:$C$5000="D")*('📋 Daily Log'!$I$5:$I$5000))} -> 97310 | D27: {=IFERROR(SUMPRODUCT(('📋 Daily Log'!$C$5:$C$5000="D")*('📋 Daily Log'!$I$5:$I$5000))/SUMPRODUCT(('📋 Daily Log'!$C$5:$C$5000="D")*1),0)} -> 8109.1667 | E27: {=SUMPRODUCT(('📋 Daily Log'!$C$5:$C$5000="D")*('📋 Daily Log'!$K$5:$K$5000))} -> 1540 | F27: {=IFERROR(SUMPRODUCT(('📋 Daily Log'!$C$5:$C$5000="D")*('📋 Daily Log'!$K$5:$K$5000))/(SUMPRODUCT(('📋 Daily Log'!$C$5:$C$5000="D")*('📋 Daily Log'!$J$5:$J$5000))-SUMPRODUCT(('📋 Daily Log'!$C$5:$C$5000="D")*('📋 Daily Log'!$M$5:$M$5000))),0)} -> 9.8528471 | G27: {=SUMPRODUCT(('📋 Daily Log'!$C$5:$C$5000="D")*('📋 Daily Log'!$M$5:$M$5000))} -> 12.4 | H27: {=IFERROR(SUMPRODUCT(('📋 Daily Log'!$C$5:$C$5000="D")*('📋 Daily Log'!$M$5:$M$5000))/SUMPRODUCT(('📋 Daily Log'!$C$5:$C$5000="D")*('📋 Daily Log'!$J$5:$J$5000)),0)} -> 0.07350326
A28: A | B28: {=SUMPRODUCT(('📋 Daily Log'!$C$5:$C$5000="A")*1)} -> 11 | C28: {=SUMPRODUCT(('📋 Daily Log'!$C$5:$C$5000="A")*('📋 Daily Log'!$I$5:$I$5000))} -> 87122 | D28: {=IFERROR(SUMPRODUCT(('📋 Daily Log'!$C$5:$C$5000="A")*('📋 Daily Log'!$I$5:$I$5000))/SUMPRODUCT(('📋 Daily Log'!$C$5:$C$5000="A")*1),0)} -> 7920.1818 | E28: {=SUMPRODUCT(('📋 Daily Log'!$C$5:$C$5000="A")*('📋 Daily Log'!$K$5:$K$5000))} -> 1323 | F28: {=IFERROR(SUMPRODUCT(('📋 Daily Log'!$C$5:$C$5000="A")*('📋 Daily Log'!$K$5:$K$5000))/(SUMPRODUCT(('📋 Daily Log'!$C$5:$C$5000="A")*('📋 Daily Log'!$J$5:$J$5000))-SUMPRODUCT(('📋 Daily Log'!$C$5:$C$5000="A")*('📋 Daily Log'!$M$5:$M$5000))),0)} -> 9.080302 | G28: {=SUMPRODUCT(('📋 Daily Log'!$C$5:$C$5000="A")*('📋 Daily Log'!$M$5:$M$5000))} -> 17.3 | H28: {=IFERROR(SUMPRODUCT(('📋 Daily Log'!$C$5:$C$5000="A")*('📋 Daily Log'!$M$5:$M$5000))/SUMPRODUCT(('📋 Daily Log'!$C$5:$C$5000="A")*('📋 Daily Log'!$J$5:$J$5000)),0)} -> 0.10613497
A30: 🛢 PERFORMANCE BY RIG
A31: Name | B31: Jobs | C31: Revenue | D31: Avg/Job | E31: Joints | F31: Jts/Hr | G31: NPT Hrs | H31: NPT%
A32: RIG-01 | B32: =SUMPRODUCT(('📋 Daily Log'!$D$5:$D$5000="RIG-01")*1) -> 9 | C32: =SUMPRODUCT(('📋 Daily Log'!$D$5:$D$5000="RIG-01")*('📋 Daily Log'!$I$5:$I$5000)) -> 73374 | D32: =IFERROR(SUMPRODUCT(('📋 Daily Log'!$D$5:$D$5000="RIG-01")*('📋 Daily Log'!$I$5:$I$5000))/SUMPRODUCT(('📋 Daily Log'!$D$5:$D$5000="RIG-01")*1),0) -> 8152.6667 | E32: =SUMPRODUCT(('📋 Daily Log'!$D$5:$D$5000="RIG-01")*('📋 Daily Log'!$K$5:$K$5000)) -> 952 | F32: =IFERROR(SUMPRODUCT(('📋 Daily Log'!$D$5:$D$5000="RIG-01")*('📋 Daily Log'!$K$5:$K$5000))/(SUMPRODUCT(('📋 Daily Log'!$D$5:$D$5000="RIG-01")*('📋 Daily Log'!$J$5:$J$5000))-SUMPRODUCT(('📋 Daily Log'!$D$5:$D$5000="RIG-01")*('📋 Daily Log'!$M$5:$M$5000))),0) -> 10.404372 | G32: =SUMPRODUCT(('📋 Daily Log'!$D$5:$D$5000="RIG-01")*('📋 Daily Log'!$M$5:$M$5000)) -> 6.6 | H32: =IFERROR(SUMPRODUCT(('📋 Daily Log'!$D$5:$D$5000="RIG-01")*('📋 Daily Log'!$M$5:$M$5000))/SUMPRODUCT(('📋 Daily Log'!$D$5:$D$5000="RIG-01")*('📋 Daily Log'!$J$5:$J$5000)),0) -> 0.067278287
A33: RIG-02 | B33: =SUMPRODUCT(('📋 Daily Log'!$D$5:$D$5000="RIG-02")*1) -> 11 | C33: =SUMPRODUCT(('📋 Daily Log'!$D$5:$D$5000="RIG-02")*('📋 Daily Log'!$I$5:$I$5000)) -> 113105 | D33: =IFERROR(SUMPRODUCT(('📋 Daily Log'!$D$5:$D$5000="RIG-02")*('📋 Daily Log'!$I$5:$I$5000))/SUMPRODUCT(('📋 Daily Log'!$D$5:$D$5000="RIG-02")*1),0) -> 10282.273 | E33: =SUMPRODUCT(('📋 Daily Log'!$D$5:$D$5000="RIG-02")*('📋 Daily Log'!$K$5:$K$5000)) -> 1371 | F33: =IFERROR(SUMPRODUCT(('📋 Daily Log'!$D$5:$D$5000="RIG-02")*('📋 Daily Log'!$K$5:$K$5000))/(SUMPRODUCT(('📋 Daily Log'!$D$5:$D$5000="RIG-02")*('📋 Daily Log'!$J$5:$J$5000))-SUMPRODUCT(('📋 Daily Log'!$D$5:$D$5000="RIG-02")*('📋 Daily Log'!$M$5:$M$5000))),0) -> 9.5076283 | G33: =SUMPRODUCT(('📋 Daily Log'!$D$5:$D$5000="RIG-02")*('📋 Daily Log'!$M$5:$M$5000)) -> 9 | H33: =IFERROR(SUMPRODUCT(('📋 Daily Log'!$D$5:$D$5000="RIG-02")*('📋 Daily Log'!$M$5:$M$5000))/SUMPRODUCT(('📋 Daily Log'!$D$5:$D$5000="RIG-02")*('📋 Daily Log'!$J$5:$J$5000)),0) -> 0.058746736
A34: RIG-03 | B34: =SUMPRODUCT(('📋 Daily Log'!$D$5:$D$5000="RIG-03")*1) -> 6 | C34: =SUMPRODUCT(('📋 Daily Log'!$D$5:$D$5000="RIG-03")*('📋 Daily Log'!$I$5:$I$5000)) -> 52867 | D34: =IFERROR(SUMPRODUCT(('📋 Daily Log'!$D$5:$D$5000="RIG-03")*('📋 Daily Log'!$I$5:$I$5000))/SUMPRODUCT(('📋 Daily Log'!$D$5:$D$5000="RIG-03")*1),0) -> 8811.1667 | E34: =SUMPRODUCT(('📋 Daily Log'!$D$5:$D$5000="RIG-03")*('📋 Daily Log'!$K$5:$K$5000)) -> 427 | F34: =IFERROR(SUMPRODUCT(('📋 Daily Log'!$D$5:$D$5000="RIG-03")*('📋 Daily Log'!$K$5:$K$5000))/(SUMPRODUCT(('📋 Daily Log'!$D$5:$D$5000="RIG-03")*('📋 Daily Log'!$J$5:$J$5000))-SUMPRODUCT(('📋 Daily Log'!$D$5:$D$5000="RIG-03")*('📋 Daily Log'!$M$5:$M$5000))),0) -> 7.6114082 | G34: =SUMPRODUCT(('📋 Daily Log'!$D$5:$D$5000="RIG-03")*('📋 Daily Log'!$M$5:$M$5000)) -> 8.1 | H34: =IFERROR(SUMPRODUCT(('📋 Daily Log'!$D$5:$D$5000="RIG-03")*('📋 Daily Log'!$M$5:$M$5000))/SUMPRODUCT(('📋 Daily Log'!$D$5:$D$5000="RIG-03")*('📋 Daily Log'!$J$5:$J$5000)),0) -> 0.12616822
A35: RIG-04 | B35: =SUMPRODUCT(('📋 Daily Log'!$D$5:$D$5000="RIG-04")*1) -> 14 | C35: =SUMPRODUCT(('📋 Daily Log'!$D$5:$D$5000="RIG-04")*('📋 Daily Log'!$I$5:$I$5000)) -> 122013 | D35: =IFERROR(SUMPRODUCT(('📋 Daily Log'!$D$5:$D$5000="RIG-04")*('📋 Daily Log'!$I$5:$I$5000))/SUMPRODUCT(('📋 Daily Log'!$D$5:$D$5000="RIG-04")*1),0) -> 8715.2143 | E35: =SUMPRODUCT(('📋 Daily Log'!$D$5:$D$5000="RIG-04")*('📋 Daily Log'!$K$5:$K$5000)) -> 1748 | F35: =IFERROR(SUMPRODUCT(('📋 Daily Log'!$D$5:$D$5000="RIG-04")*('📋 Daily Log'!$K$5:$K$5000))/(SUMPRODUCT(('📋 Daily Log'!$D$5:$D$5000="RIG-04")*('📋 Daily Log'!$J$5:$J$5000))-SUMPRODUCT(('📋 Daily Log'!$D$5:$D$5000="RIG-04")*('📋 Daily Log'!$M$5:$M$5000))),0) -> 8.7662989 | G35: =SUMPRODUCT(('📋 Daily Log'!$D$5:$D$5000="RIG-04")*('📋 Daily Log'!$M$5:$M$5000)) -> 13.4 | H35: =IFERROR(SUMPRODUCT(('📋 Daily Log'!$D$5:$D$5000="RIG-04")*('📋 Daily Log'!$M$5:$M$5000))/SUMPRODUCT(('📋 Daily Log'!$D$5:$D$5000="RIG-04")*('📋 Daily Log'!$J$5:$J$5000)),0) -> 0.062969925
A36: RIG-05 | B36: =SUMPRODUCT(('📋 Daily Log'!$D$5:$D$5000="RIG-05")*1) -> 10 | C36: =SUMPRODUCT(('📋 Daily Log'!$D$5:$D$5000="RIG-05")*('📋 Daily Log'!$I$5:$I$5000)) -> 89768 | D36: =IFERROR(SUMPRODUCT(('📋 Daily Log'!$D$5:$D$5000="RIG-05")*('📋 Daily Log'!$I$5:$I$5000))/SUMPRODUCT(('📋 Daily Log'!$D$5:$D$5000="RIG-05")*1),0) -> 8976.8 | E36: =SUMPRODUCT(('📋 Daily Log'!$D$5:$D$5000="RIG-05")*('📋 Daily Log'!$K$5:$K$5000)) -> 1157 | F36: =IFERROR(SUMPRODUCT(('📋 Daily Log'!$D$5:$D$5000="RIG-05")*('📋 Daily Log'!$K$5:$K$5000))/(SUMPRODUCT(('📋 Daily Log'!$D$5:$D$5000="RIG-05")*('📋 Daily Log'!$J$5:$J$5000))-SUMPRODUCT(('📋 Daily Log'!$D$5:$D$5000="RIG-05")*('📋 Daily Log'!$M$5:$M$5000))),0) -> 7.8440678 | G36: =SUMPRODUCT(('📋 Daily Log'!$D$5:$D$5000="RIG-05")*('📋 Daily Log'!$M$5:$M$5000)) -> 8 | H36: =IFERROR(SUMPRODUCT(('📋 Daily Log'!$D$5:$D$5000="RIG-05")*('📋 Daily Log'!$M$5:$M$5000))/SUMPRODUCT(('📋 Daily Log'!$D$5:$D$5000="RIG-05")*('📋 Daily Log'!$J$5:$J$5000)),0) -> 0.051446945
A37: RIG-06 | B37: =SUMPRODUCT(('📋 Daily Log'!$D$5:$D$5000="RIG-06")*1) -> 13 | C37: =SUMPRODUCT(('📋 Daily Log'!$D$5:$D$5000="RIG-06")*('📋 Daily Log'!$I$5:$I$5000)) -> 117183 | D37: =IFERROR(SUMPRODUCT(('📋 Daily Log'!$D$5:$D$5000="RIG-06")*('📋 Daily Log'!$I$5:$I$5000))/SUMPRODUCT(('📋 Daily Log'!$D$5:$D$5000="RIG-06")*1),0) -> 9014.0769 | E37: =SUMPRODUCT(('📋 Daily Log'!$D$5:$D$5000="RIG-06")*('📋 Daily Log'!$K$5:$K$5000)) -> 1295 | F37: =IFERROR(SUMPRODUCT(('📋 Daily Log'!$D$5:$D$5000="RIG-06")*('📋 Daily Log'!$K$5:$K$5000))/(SUMPRODUCT(('📋 Daily Log'!$D$5:$D$5000="RIG-06")*('📋 Daily Log'!$J$5:$J$5000))-SUMPRODUCT(('📋 Daily Log'!$D$5:$D$5000="RIG-06")*('📋 Daily Log'!$M$5:$M$5000))),0) -> 9.1519435 | G37: =SUMPRODUCT(('📋 Daily Log'!$D$5:$D$5000="RIG-06")*('📋 Daily Log'!$M$5:$M$5000)) -> 26.4 | H37: =IFERROR(SUMPRODUCT(('📋 Daily Log'!$D$5:$D$5000="RIG-06")*('📋 Daily Log'!$M$5:$M$5000))/SUMPRODUCT(('📋 Daily Log'!$D$5:$D$5000="RIG-06")*('📋 Daily Log'!$J$5:$J$5000)),0) -> 0.15723645
A39: 🔧 PERFORMANCE BY SERVICE TYPE
A40: Name | B40: Jobs | C40: Revenue | D40: Avg/Job | E40: Joints | F40: Jts/Hr | G40: NPT Hrs | H40: NPT%
A41: Casing | B41: =SUMPRODUCT(('📋 Daily Log'!$F$5:$F$5000="Casing")*1) -> 17 | C41: =SUMPRODUCT(('📋 Daily Log'!$F$5:$F$5000="Casing")*('📋 Daily Log'!$I$5:$I$5000)) -> 140101 | D41: =IFERROR(SUMPRODUCT(('📋 Daily Log'!$F$5:$F$5000="Casing")*('📋 Daily Log'!$I$5:$I$5000))/SUMPRODUCT(('📋 Daily Log'!$F$5:$F$5000="Casing")*1),0) -> 8241.2353 | E41: =SUMPRODUCT(('📋 Daily Log'!$F$5:$F$5000="Casing")*('📋 Daily Log'!$K$5:$K$5000)) -> 2073 | F41: =IFERROR(SUMPRODUCT(('📋 Daily Log'!$F$5:$F$5000="Casing")*('📋 Daily Log'!$K$5:$K$5000))/(SUMPRODUCT(('📋 Daily Log'!$F$5:$F$5000="Casing")*('📋 Daily Log'!$J$5:$J$5000))-SUMPRODUCT(('📋 Daily Log'!$F$5:$F$5000="Casing")*('📋 Daily Log'!$M$5:$M$5000))),0) -> 10.313433 | G41: =SUMPRODUCT(('📋 Daily Log'!$F$5:$F$5000="Casing")*('📋 Daily Log'!$M$5:$M$5000)) -> 17.5 | H41: =IFERROR(SUMPRODUCT(('📋 Daily Log'!$F$5:$F$5000="Casing")*('📋 Daily Log'!$M$5:$M$5000))/SUMPRODUCT(('📋 Daily Log'!$F$5:$F$5000="Casing")*('📋 Daily Log'!$J$5:$J$5000)),0) -> 0.080091533
A42: Combo | B42: =SUMPRODUCT(('📋 Daily Log'!$F$5:$F$5000="Combo")*1) -> 15 | C42: =SUMPRODUCT(('📋 Daily Log'!$F$5:$F$5000="Combo")*('📋 Daily Log'!$I$5:$I$5000)) -> 124376 | D42: =IFERROR(SUMPRODUCT(('📋 Daily Log'!$F$5:$F$5000="Combo")*('📋 Daily Log'!$I$5:$I$5000))/SUMPRODUCT(('📋 Daily Log'!$F$5:$F$5000="Combo")*1),0) -> 8291.7333 | E42: =SUMPRODUCT(('📋 Daily Log'!$F$5:$F$5000="Combo")*('📋 Daily Log'!$K$5:$K$5000)) -> 1325 | F42: =IFERROR(SUMPRODUCT(('📋 Daily Log'!$F$5:$F$5000="Combo")*('📋 Daily Log'!$K$5:$K$5000))/(SUMPRODUCT(('📋 Daily Log'!$F$5:$F$5000="Combo")*('📋 Daily Log'!$J$5:$J$5000))-SUMPRODUCT(('📋 Daily Log'!$F$5:$F$5000="Combo")*('📋 Daily Log'!$M$5:$M$5000))),0) -> 7.7987051 | G42: =SUMPRODUCT(('📋 Daily Log'!$F$5:$F$5000="Combo")*('📋 Daily Log'!$M$5:$M$5000)) -> 25.5 | H42: =IFERROR(SUMPRODUCT(('📋 Daily Log'!$F$5:$F$5000="Combo")*('📋 Daily Log'!$M$5:$M$5000))/SUMPRODUCT(('📋 Daily Log'!$F$5:$F$5000="Combo")*('📋 Daily Log'!$J$5:$J$5000)),0) -> 0.13050154
A43: Tubing | B43: =SUMPRODUCT(('📋 Daily Log'!$F$5:$F$5000="Tubing")*1) -> 12 | C43: =SUMPRODUCT(('📋 Daily Log'!$F$5:$F$5000="Tubing")*('📋 Daily Log'!$I$5:$I$5000)) -> 124179 | D43: =IFERROR(SUMPRODUCT(('📋 Daily Log'!$F$5:$F$5000="Tubing")*('📋 Daily Log'!$I$5:$I$5000))/SUMPRODUCT(('📋 Daily Log'!$F$5:$F$5000="Tubing")*1),0) -> 10348.25 | E43: =SUMPRODUCT(('📋 Daily Log'!$F$5:$F$5000="Tubing")*('📋 Daily Log'!$K$5:$K$5000)) -> 992 | F43: =IFERROR(SUMPRODUCT(('📋 Daily Log'!$F$5:$F$5000="Tubing")*('📋 Daily Log'!$K$5:$K$5000))/(SUMPRODUCT(('📋 Daily Log'!$F$5:$F$5000="Tubing")*('📋 Daily Log'!$J$5:$J$5000))-SUMPRODUCT(('📋 Daily Log'!$F$5:$F$5000="Tubing")*('📋 Daily Log'!$M$5:$M$5000))),0) -> 7.4811463 | G43: =SUMPRODUCT(('📋 Daily Log'!$F$5:$F$5000="Tubing")*('📋 Daily Log'!$M$5:$M$5000)) -> 16.5 | H43: =IFERROR(SUMPRODUCT(('📋 Daily Log'!$F$5:$F$5000="Tubing")*('📋 Daily Log'!$M$5:$M$5000))/SUMPRODUCT(('📋 Daily Log'!$F$5:$F$5000="Tubing")*('📋 Daily Log'!$J$5:$J$5000)),0) -> 0.11066398
A44: CDS | B44: =SUMPRODUCT(('📋 Daily Log'!$F$5:$F$5000="CDS")*1) -> 11 | C44: =SUMPRODUCT(('📋 Daily Log'!$F$5:$F$5000="CDS")*('📋 Daily Log'!$I$5:$I$5000)) -> 111017 | D44: =IFERROR(SUMPRODUCT(('📋 Daily Log'!$F$5:$F$5000="CDS")*('📋 Daily Log'!$I$5:$I$5000))/SUMPRODUCT(('📋 Daily Log'!$F$5:$F$5000="CDS")*1),0) -> 10092.455 | E44: =SUMPRODUCT(('📋 Daily Log'!$F$5:$F$5000="CDS")*('📋 Daily Log'!$K$5:$K$5000)) -> 1608 | F44: =IFERROR(SUMPRODUCT(('📋 Daily Log'!$F$5:$F$5000="CDS")*('📋 Daily Log'!$K$5:$K$5000))/(SUMPRODUCT(('📋 Daily Log'!$F$5:$F$5000="CDS")*('📋 Daily Log'!$J$5:$J$5000))-SUMPRODUCT(('📋 Daily Log'!$F$5:$F$5000="CDS")*('📋 Daily Log'!$M$5:$M$5000))),0) -> 9.0286356 | G44: =SUMPRODUCT(('📋 Daily Log'!$F$5:$F$5000="CDS")*('📋 Daily Log'!$M$5:$M$5000)) -> 6.5 | H44: =IFERROR(SUMPRODUCT(('📋 Daily Log'!$F$5:$F$5000="CDS")*('📋 Daily Log'!$M$5:$M$5000))/SUMPRODUCT(('📋 Daily Log'!$F$5:$F$5000="CDS")*('📋 Daily Log'!$J$5:$J$5000)),0) -> 0.035211268
A45: PULD | B45: =SUMPRODUCT(('📋 Daily Log'!$F$5:$F$5000="PULD")*1) -> 8 | C45: =SUMPRODUCT(('📋 Daily Log'!$F$5:$F$5000="PULD")*('📋 Daily Log'!$I$5:$I$5000)) -> 68637 | D45: =IFERROR(SUMPRODUCT(('📋 Daily Log'!$F$5:$F$5000="PULD")*('📋 Daily Log'!$I$5:$I$5000))/SUMPRODUCT(('📋 Daily Log'!$F$5:$F$5000="PULD")*1),0) -> 8579.625 | E45: =SUMPRODUCT(('📋 Daily Log'!$F$5:$F$5000="PULD")*('📋 Daily Log'!$K$5:$K$5000)) -> 952 | F45: =IFERROR(SUMPRODUCT(('📋 Daily Log'!$F$5:$F$5000="PULD")*('📋 Daily Log'!$K$5:$K$5000))/(SUMPRODUCT(('📋 Daily Log'!$F$5:$F$5000="PULD")*('📋 Daily Log'!$J$5:$J$5000))-SUMPRODUCT(('📋 Daily Log'!$F$5:$F$5000="PULD")*('📋 Daily Log'!$M$5:$M$5000))),0) -> 9.6551724 | G45: =SUMPRODUCT(('📋 Daily Log'!$F$5:$F$5000="PULD")*('📋 Daily Log'!$M$5:$M$5000)) -> 5.5 | H45: =IFERROR(SUMPRODUCT(('📋 Daily Log'!$F$5:$F$5000="PULD")*('📋 Daily Log'!$M$5:$M$5000))/SUMPRODUCT(('📋 Daily Log'!$F$5:$F$5000="PULD")*('📋 Daily Log'!$J$5:$J$5000)),0) -> 0.052833814
A47: ⚠️ NPT HOURS BY ROOT CAUSE
A48: NPT Category | B48: Total Hrs | C48: % of NPT | D48: Cumulative %
A49: Process | B49: =SUMPRODUCT(('📋 Daily Log'!$N$5:$N$5000="Process")*('📋 Daily Log'!$M$5:$M$5000)) -> 27.7 | C49: =IFERROR(B49/SUM('📋 Daily Log'!$M$5:$M$5000),0) -> 0.38741259 | D49: =SUM(C49:C49) -> 0.38741259
A50: Personnel | B50: =SUMPRODUCT(('📋 Daily Log'!$N$5:$N$5000="Personnel")*('📋 Daily Log'!$M$5:$M$5000)) -> 17.2 | C50: =IFERROR(B50/SUM('📋 Daily Log'!$M$5:$M$5000),0) -> 0.24055944 | D50: =SUM(C49:C50) -> 0.62797203
A51: Equipment | B51: =SUMPRODUCT(('📋 Daily Log'!$N$5:$N$5000="Equipment")*('📋 Daily Log'!$M$5:$M$5000)) -> 11.7 | C51: =IFERROR(B51/SUM('📋 Daily Log'!$M$5:$M$5000),0) -> 0.16363636 | D51: =SUM(C49:C51) -> 0.79160839
A52: Weather | B52: =SUMPRODUCT(('📋 Daily Log'!$N$5:$N$5000="Weather")*('📋 Daily Log'!$M$5:$M$5000)) -> 7.6 | C52: =IFERROR(B52/SUM('📋 Daily Log'!$M$5:$M$5000),0) -> 0.10629371 | D52: =SUM(C49:C52) -> 0.8979021
A53: Client/3rd | B53: =SUMPRODUCT(('📋 Daily Log'!$N$5:$N$5000="Client/3rd")*('📋 Daily Log'!$M$5:$M$5000)) -> 7.3 | C53: =IFERROR(B53/SUM('📋 Daily Log'!$M$5:$M$5000),0) -> 0.1020979 | D53: =SUM(C49:C53) -> 1
...

Sheet 📊 Daily Dashboard
A1: 📊 TRS DAILY OPERATIONS DASHBOARD
A2: =" Tubular Running Services · Eastern Province, KSA · Updated: "&TEXT(TODAY(),"DD MMM YYYY")&" · " -> Tubular Running Services · Eastern Province, KSA · Updated: 30 Rab. II 2026 ·
A4: =" 📅 LATEST DAY: "&TEXT(Pivot!A31,"DD MMMM YYYY") -> 📅 LATEST DAY: 29 Rabiʻ II 2026
A7: 💰 LATEST DAY REVENUE | D7: 📋 TODAY JOBS | F7: ⏱ TODAY NPT HRS | H7: 💰 MTD REVENUE
A8: =Pivot!B31 -> 25952 | D8: =Pivot!C31 -> 3 | F8: =Pivot!D31 -> 3.5 | H8: =SUM('📋 Daily Log'!$I$5:$I$5000) -> 568310
A9: =TEXT(Pivot!A31,"DD MMM YYYY") -> 29 Rab. II 2026 | D9: "Jobs on latest day" | F9: ="NPT%: "&TEXT(Pivot!G31,"0.0%") -> NPT%: 7.4% | H9: "Month to Date"
A12: 📊 MONTH-TO-DATE SUMMARY
A13: Total Revenue | B13: Total Jobs | C13: NPT % | D13: Avg Rev/Job | E13: Total Joints | F13: Jts / Hr | G13: Completion% | H13: Avg Hrs/Job
A14: =SUM('📋 Daily Log'!$I$5:$I$5000) -> 568310 | B14: =SUMPRODUCT(('📋 Daily Log'!$C$5:$C$5000<>"")*1) -> 63 | C14: =IFERROR(SUM('📋 Daily Log'!$M$5:$M$5000)/SUM('📋 Daily Log'!$J$5:$J$5000),0) -> 0.083949748 | D14: =IFERROR(SUM('📋 Daily Log'!$I$5:$I$5000)/SUMPRODUCT(('📋 Daily Log'!$C$5:$C$5000<>"")*1),0) -> 9020.7937 | E14: =SUM('📋 Daily Log'!$K$5:$K$5000) -> 6950 | F14: =IFERROR(SUM('📋 Daily Log'!$K$5:$K$5000)/(SUM('📋 Daily Log'!$J$5:$J$5000)-SUM('📋 Daily Log'!$M$5:$M$5000)),0) -> 8.9079723 | G14: =IFERROR(COUNTIF('📋 Daily Log'!$O$5:$O$5000,"FINISHED")/SUMPRODUCT(('📋 Daily Log'!$C$5:$C$5000<>"")*1),0) -> 0.88888889 | H14: =IFERROR(SUM('📋 Daily Log'!$J$5:$J$5000)/SUMPRODUCT(('📋 Daily Log'!$C$5:$C$5000<>"")*1),0) -> 13.519048
A16: 📋 DAILY PERFORMANCE TABLE
A17: Date | B17: Revenue | C17: Jobs | D17: NPT Hrs | E17: Avg Rev/Job | F17: Cumul. Rev | G17: NPT% | H17: Status
A18: =Pivot!A3 -> 46113 | B18: =Pivot!B3 -> 26849 | C18: =Pivot!C3 -> 3 | D18: =Pivot!D3 -> 3.6 | E18: =Pivot!E3 -> 8949.6667 | F18: =Pivot!F3 -> 26849 | G18: =Pivot!G3 -> 0.11842105 | H18: =IF(Pivot!G3>0.1,"🔴 High NPT",IF(Pivot!G3>0.05,"🟡 Watch","🟢 Good")) -> 🔴 High NPT
A19: =Pivot!A4 -> 46114 | B19: =Pivot!B4 -> 16932 | C19: =Pivot!C4 -> 2 | D19: =Pivot!D4 -> 3.4 | E19: =Pivot!E4 -> 8466 | F19: =Pivot!F4 -> 43781 | G19: =Pivot!G4 -> 0.10793651 | H19: =IF(Pivot!G4>0.1,"🔴 High NPT",IF(Pivot!G4>0.05,"🟡 Watch","🟢 Good")) -> 🔴 High NPT
A20: =Pivot!A5 -> 46115 | B20: =Pivot!B5 -> 13398 | C20: =Pivot!C5 -> 1 | D20: =Pivot!D5 -> 0 | E20: =Pivot!E5 -> 13398 | F20: =Pivot!F5 -> 57179 | G20: =Pivot!G5 -> 0 | H20: =IF(Pivot!G5>0.1,"🔴 High NPT",IF(Pivot!G5>0.05,"🟡 Watch","🟢 Good")) -> 🟢 Good
A21: =Pivot!A6 -> 46116 | B21: =Pivot!B6 -> 16369 | C21: =Pivot!C6 -> 2 | D21: =Pivot!D6 -> 0 | E21: =Pivot!E6 -> 8184.5 | F21: =Pivot!F6 -> 73548 | G21: =Pivot!G6 -> 0 | H21: =IF(Pivot!G6>0.1,"🔴 High NPT",IF(Pivot!G6>0.05,"🟡 Watch","🟢 Good")) -> 🟢 Good
A22: =Pivot!A7 -> 46117 | B22: =Pivot!B7 -> 32286 | C22: =Pivot!C7 -> 3 | D22: =Pivot!D7 -> 0 | E22: =Pivot!E7 -> 10762 | F22: =Pivot!F7 -> 105834 | G22: =Pivot!G7 -> 0 | H22: =IF(Pivot!G7>0.1,"🔴 High NPT",IF(Pivot!G7>0.05,"🟡 Watch","🟢 Good")) -> 🟢 Good
A23: =Pivot!A8 -> 46118 | B23: =Pivot!B8 -> 26608 | C23: =Pivot!C8 -> 3 | D23: =Pivot!D8 -> 6.9 | E23: =Pivot!E8 -> 8869.3333 | F23: =Pivot!F8 -> 132442 | G23: =Pivot!G8 -> 0.14806867 | H23: =IF(Pivot!G8>0.1,"🔴 High NPT",IF(Pivot!G8>0.05,"🟡 Watch","🟢 Good")) -> 🔴 High NPT
A24: =Pivot!A9 -> 46119 | B24: =Pivot!B9 -> 10855 | C24: =Pivot!C9 -> 2 | D24: =Pivot!D9 -> 4.2 | E24: =Pivot!E9 -> 5427.5 | F24: =Pivot!F9 -> 143297 | G24: =Pivot!G9 -> 0.17948718 | H24: =IF(Pivot!G9>0.1,"🔴 High NPT",IF(Pivot!G9>0.05,"🟡 Watch","🟢 Good")) -> 🔴 High NPT
A25: =Pivot!A10 -> 46120 | B25: =Pivot!B10 -> 15946 | C25: =Pivot!C10 -> 2 | D25: =Pivot!D10 -> 0 | E25: =Pivot!E10 -> 7973 | F25: =Pivot!F10 -> 159243 | G25: =Pivot!G10 -> 0 | H25: =IF(Pivot!G10>0.1,"🔴 High NPT",IF(Pivot!G10>0.05,"🟡 Watch","🟢 Good")) -> 🟢 Good
A26: =Pivot!A11 -> 46121 | B26: =Pivot!B11 -> 22837 | C26: =Pivot!C11 -> 3 | D26: =Pivot!D11 -> 5 | E26: =Pivot!E11 -> 7612.3333 | F26: =Pivot!F11 -> 182080 | G26: =Pivot!G11 -> 0.11160714 | H26: =IF(Pivot!G11>0.1,"🔴 High NPT",IF(Pivot!G11>0.05,"🟡 Watch","🟢 Good")) -> 🔴 High NPT
A27: =Pivot!A12 -> 46122 | B27: =Pivot!B12 -> 10826 | C27: =Pivot!C12 -> 1 | D27: =Pivot!D12 -> 0 | E27: =Pivot!E12 -> 10826 | F27: =Pivot!F12 -> 192906 | G27: =Pivot!G12 -> 0 | H27: =IF(Pivot!G12>0.1,"🔴 High NPT",IF(Pivot!G12>0.05,"🟡 Watch","🟢 Good")) -> 🟢 Good
A28: =Pivot!A13 -> 46123 | B28: =Pivot!B13 -> 24771 | C28: =Pivot!C13 -> 2 | D28: =Pivot!D13 -> 0 | E28: =Pivot!E13 -> 12385.5 | F28: =Pivot!F13 -> 217677 | G28: =Pivot!G13 -> 0 | H28: =IF(Pivot!G13>0.1,"🔴 High NPT",IF(Pivot!G13>0.05,"🟡 Watch","🟢 Good")) -> 🟢 Good
A29: =Pivot!A14 -> 46124 | B29: =Pivot!B14 -> 22736 | C29: =Pivot!C14 -> 3 | D29: =Pivot!D14 -> 5.8 | E29: =Pivot!E14 -> 7578.6667 | F29: =Pivot!F14 -> 240413 | G29: =Pivot!G14 -> 0.1530343 | H29: =IF(Pivot!G14>0.1,"🔴 High NPT",IF(Pivot!G14>0.05,"🟡 Watch","🟢 Good")) -> 🔴 High NPT
... A46: =Pivot!A31 -> 46141 | B46: =Pivot!B31 -> 25952 | C46: =Pivot!C31 -> 3 | D46: =Pivot!D31 -> 3.5 | E46: =Pivot!E31 -> 8650.6667 | F46: =Pivot!F31 -> 568310 | G46: =Pivot!G31 -> 0.074309979 | H46: =IF(Pivot!G31>0.1,"🔴 High NPT",IF(Pivot!G31>0.05,"🟡 Watch","🟢 Good")) -> 🟡 Watch
A48: CONFIDENTIAL · FOR MANAGEMENT USE ONLY · TRS Daily Dashboard · Source: 📋 Daily Log

Sheet Pivot
A1: PIVOT — Auto Daily Aggregation (source for all dashboards)
A2: Date | B2: Daily Revenue | C2: Jobs | D2: NPT Hrs | E2: Avg Rev/Job | F2: Cumul. Revenue | G2: Daily NPT%
A3: 46113 | B3: =SUMPRODUCT(('📋 Daily Log'!$B$5:$B$5000=A3)*('📋 Daily Log'!$I$5:$I$5000)) -> 26849 | C3: =SUMPRODUCT(('📋 Daily Log'!$B$5:$B$5000=A3)*1) -> 3 | D3: =SUMPRODUCT(('📋 Daily Log'!$B$5:$B$5000=A3)*('📋 Daily Log'!$M$5:$M$5000)) -> 3.6 | E3: =IFERROR(B3/C3,0) -> 8949.6667 | F3: =SUM(B$3:B3) -> 26849 | G3: =IFERROR(SUMPRODUCT(('📋 Daily Log'!$B$5:$B$5000=A3)*('📋 Daily Log'!$M$5:$M$5000))/SUMPRODUCT(('📋 Daily Log'!$B$5:$B$5000=A3)*('📋 Daily Log'!$J$5:$J$5000)),0) -> 0.11842105
A4: 46114 | B4: =SUMPRODUCT(('📋 Daily Log'!$B$5:$B$5000=A4)*('📋 Daily Log'!$I$5:$I$5000)) -> 16932 | C4: =SUMPRODUCT(('📋 Daily Log'!$B$5:$B$5000=A4)*1) -> 2 | D4: =SUMPRODUCT(('📋 Daily Log'!$B$5:$B$5000=A4)*('📋 Daily Log'!$M$5:$M$5000)) -> 3.4 | E4: =IFERROR(B4/C4,0) -> 8466 | F4: =SUM(B$3:B4) -> 43781 | G4: =IFERROR(SUMPRODUCT(('📋 Daily Log'!$B$5:$B$5000=A4)*('📋 Daily Log'!$M$5:$M$5000))/SUMPRODUCT(('📋 Daily Log'!$B$5:$B$5000=A4)*('📋 Daily Log'!$J$5:$J$5000)),0) -> 0.10793651
A5: 46115 | B5: =SUMPRODUCT(('📋 Daily Log'!$B$5:$B$5000=A5)*('📋 Daily Log'!$I$5:$I$5000)) -> 13398 | C5: =SUMPRODUCT(('📋 Daily Log'!$B$5:$B$5000=A5)*1) -> 1 | D5: =SUMPRODUCT(('📋 Daily Log'!$B$5:$B$5000=A5)*('📋 Daily Log'!$M$5:$M$5000)) -> 0 | E5: =IFERROR(B5/C5,0) -> 13398 | F5: =SUM(B$3:B5) -> 57179 | G5: =IFERROR(SUMPRODUCT(('📋 Daily Log'!$B$5:$B$5000=A5)*('📋 Daily Log'!$M$5:$M$5000))/SUMPRODUCT(('📋 Daily Log'!$B$5:$B$5000=A5)*('📋 Daily Log'!$J$5:$J$5000)),0) -> 0
A6: 46116 | B6: =SUMPRODUCT(('📋 Daily Log'!$B$5:$B$5000=A6)*('📋 Daily Log'!$I$5:$I$5000)) -> 16369 | C6: =SUMPRODUCT(('📋 Daily Log'!$B$5:$B$5000=A6)*1) -> 2 | D6: =SUMPRODUCT(('📋 Daily Log'!$B$5:$B$5000=A6)*('📋 Daily Log'!$M$5:$M$5000)) -> 0 | E6: =IFERROR(B6/C6,0) -> 8184.5 | F6: =SUM(B$3:B6) -> 73548 | G6: =IFERROR(SUMPRODUCT(('📋 Daily Log'!$B$5:$B$5000=A6)*('📋 Daily Log'!$M$5:$M$5000))/SUMPRODUCT(('📋 Daily Log'!$B$5:$B$5000=A6)*('📋 Daily Log'!$J$5:$J$5000)),0) -> 0
A7: 46117 | B7: =SUMPRODUCT(('📋 Daily Log'!$B$5:$B$5000=A7)*('📋 Daily Log'!$I$5:$I$5000)) -> 32286 | C7: =SUMPRODUCT(('📋 Daily Log'!$B$5:$B$5000=A7)*1) -> 3 | D7: =SUMPRODUCT(('📋 Daily Log'!$B$5:$B$5000=A7)*('📋 Daily Log'!$M$5:$M$5000)) -> 0 | E7: =IFERROR(B7/C7,0) -> 10762 | F7: =SUM(B$3:B7) -> 105834 | G7: =IFERROR(SUMPRODUCT(('📋 Daily Log'!$B$5:$B$5000=A7)*('📋 Daily Log'!$M$5:$M$5000))/SUMPRODUCT(('📋 Daily Log'!$B$5:$B$5000=A7)*('📋 Daily Log'!$J$5:$J$5000)),0) -> 0
A8: 46118 | B8: =SUMPRODUCT(('📋 Daily Log'!$B$5:$B$5000=A8)*('📋 Daily Log'!$I$5:$I$5000)) -> 26608 | C8: =SUMPRODUCT(('📋 Daily Log'!$B$5:$B$5000=A8)*1) -> 3 | D8: =SUMPRODUCT(('📋 Daily Log'!$B$5:$B$5000=A8)*('📋 Daily Log'!$M$5:$M$5000)) -> 6.9 | E8: =IFERROR(B8/C8,0) -> 8869.3333 | F8: =SUM(B$3:B8) -> 132442 | G8: =IFERROR(SUMPRODUCT(('📋 Daily Log'!$B$5:$B$5000=A8)*('📋 Daily Log'!$M$5:$M$5000))/SUMPRODUCT(('📋 Daily Log'!$B$5:$B$5000=A8)*('📋 Daily Log'!$J$5:$J$5000)),0) -> 0.14806867
A9: 46119 | B9: =SUMPRODUCT(('📋 Daily Log'!$B$5:$B$5000=A9)*('📋 Daily Log'!$I$5:$I$5000)) -> 10855 | C9: =SUMPRODUCT(('📋 Daily Log'!$B$5:$B$5000=A9)*1) -> 2 | D9: =SUMPRODUCT(('📋 Daily Log'!$B$5:$B$5000=A9)*('📋 Daily Log'!$M$5:$M$5000)) -> 4.2 | E9: =IFERROR(B9/C9,0) -> 5427.5 | F9: =SUM(B$3:B9) -> 143297 | G9: =IFERROR(SUMPRODUCT(('📋 Daily Log'!$B$5:$B$5000=A9)*('📋 Daily Log'!$M$5:$M$5000))/SUMPRODUCT(('📋 Daily Log'!$B$5:$B$5000=A9)*('📋 Daily Log'!$J$5:$J$5000)),0) -> 0.17948718
A10: 46120 | B10: =SUMPRODUCT(('📋 Daily Log'!$B$5:$B$5000=A10)*('📋 Daily Log'!$I$5:$I$5000)) -> 15946 | C10: =SUMPRODUCT(('📋 Daily Log'!$B$5:$B$5000=A10)*1) -> 2 | D10: =SUMPRODUCT(('📋 Daily Log'!$B$5:$B$5000=A10)*('📋 Daily Log'!$M$5:$M$5000)) -> 0 | E10: =IFERROR(B10/C10,0) -> 7973 | F10: =SUM(B$3:B10) -> 159243 | G10: =IFERROR(SUMPRODUCT(('📋 Daily Log'!$B$5:$B$5000=A10)*('📋 Daily Log'!$M$5:$M$5000))/SUMPRODUCT(('📋 Daily Log'!$B$5:$B$5000=A10)*('📋 Daily Log'!$J$5:$J$5000)),0) -> 0
A11: 46121 | B11: =SUMPRODUCT(('📋 Daily Log'!$B$5:$B$5000=A11)*('📋 Daily Log'!$I$5:$I$5000)) -> 22837 | C11: =SUMPRODUCT(('📋 Daily Log'!$B$5:$B$5000=A11)*1) -> 3 | D11: =SUMPRODUCT(('📋 Daily Log'!$B$5:$B$5000=A11)*('📋 Daily Log'!$M$5:$M$5000)) -> 5 | E11: =IFERROR(B11/C11,0) -> 7612.3333 | F11: =SUM(B$3:B11) -> 182080 | G11: =IFERROR(SUMPRODUCT(('📋 Daily Log'!$B$5:$B$5000=A11)*('📋 Daily Log'!$M$5:$M$5000))/SUMPRODUCT(('📋 Daily Log'!$B$5:$B$5000=A11)*('📋 Daily Log'!$J$5:$J$5000)),0) -> 0.11160714
A12: 46122 | B12: =SUMPRODUCT(('📋 Daily Log'!$B$5:$B$5000=A12)*('📋 Daily Log'!$I$5:$I$5000)) -> 10826 | C12: =SUMPRODUCT(('📋 Daily Log'!$B$5:$B$5000=A12)*1) -> 1 | D12: =SUMPRODUCT(('📋 Daily Log'!$B$5:$B$5000=A12)*('📋 Daily Log'!$M$5:$M$5000)) -> 0 | E12: =IFERROR(B12/C12,0) -> 10826 | F12: =SUM(B$3:B12) -> 192906 | G12: =IFERROR(SUMPRODUCT(('📋 Daily Log'!$B$5:$B$5000=A12)*('📋 Daily Log'!$M$5:$M$5000))/SUMPRODUCT(('📋 Daily Log'!$B$5:$B$5000=A12)*('📋 Daily Log'!$J$5:$J$5000)),0) -> 0
A13: 46123 | B13: =SUMPRODUCT(('📋 Daily Log'!$B$5:$B$5000=A13)*('📋 Daily Log'!$I$5:$I$5000)) -> 24771 | C13: =SUMPRODUCT(('📋 Daily Log'!$B$5:$B$5000=A13)*1) -> 2 | D13: =SUMPRODUCT(('📋 Daily Log'!$B$5:$B$5000=A13)*('📋 Daily Log'!$M$5:$M$5000)) -> 0 | E13: =IFERROR(B13/C13,0) -> 12385.5 | F13: =SUM(B$3:B13) -> 217677 | G13: =IFERROR(SUMPRODUCT(('📋 Daily Log'!$B$5:$B$5000=A13)*('📋 Daily Log'!$M$5:$M$5000))/SUMPRODUCT(('📋 Daily Log'!$B$5:$B$5000=A13)*('📋 Daily Log'!$J$5:$J$5000)),0) -> 0
A14: 46124 | B14: =SUMPRODUCT(('📋 Daily Log'!$B$5:$B$5000=A14)*('📋 Daily Log'!$I$5:$I$5000)) -> 22736 | C14: =SUMPRODUCT(('📋 Daily Log'!$B$5:$B$5000=A14)*1) -> 3 | D14: =SUMPRODUCT(('📋 Daily Log'!$B$5:$B$5000=A14)*('📋 Daily Log'!$M$5:$M$5000)) -> 5.8 | E14: =IFERROR(B14/C14,0) -> 7578.6667 | F14: =SUM(B$3:B14) -> 240413 | G14: =IFERROR(SUMPRODUCT(('📋 Daily Log'!$B$5:$B$5000=A14)*('📋 Daily Log'!$M$5:$M$5000))/SUMPRODUCT(('📋 Daily Log'!$B$5:$B$5000=A14)*('📋 Daily Log'!$J$5:$J$5000)),0) -> 0.1530343
... A31: 46141 | B31: =SUMPRODUCT(('📋 Daily Log'!$B$5:$B$5000=A31)*('📋 Daily Log'!$I$5:$I$5000)) -> 25952 | C31: =SUMPRODUCT(('📋 Daily Log'!$B$5:$B$5000=A31)*1) -> 3 | D31: =SUMPRODUCT(('📋 Daily Log'!$B$5:$B$5000=A31)*('📋 Daily Log'!$M$5:$M$5000)) -> 3.5 | E31: =IFERROR(B31/C31,0) -> 8650.6667 | F31: =SUM(B$3:B31) -> 568310 | G31: =IFERROR(SUMPRODUCT(('📋 Daily Log'!$B$5:$B$5000=A31)*('📋 Daily Log'!$M$5:$M$5000))/SUMPRODUCT(('📋 Daily Log'!$B$5:$B$5000=A31)*('📋 Daily Log'!$J$5:$J$5000)),0) -> 0.074309979
